[ERROR 2016-11-19 09:27:29,448 @ 2368] (C:\Python27\lib\site-packages\django\core\handlers\base.py/handle_uncaught_exception:256) - Internal Server Error: /v1/cmdb/list/grouppost/
Traceback (most recent call last):
  File "C:\Python27\lib\site-packages\django\core\handlers\base.py", line 132, in get_response
    response = wrapped_callback(request, *callback_args, **callback_kwargs)
  File "C:\Python27\lib\site-packages\django\views\decorators\csrf.py", line 58, in wrapped_view
    return view_func(*args, **kwargs)
  File "C:\Python27\lib\site-packages\django\views\generic\base.py", line 71, in view
    return self.dispatch(request, *args, **kwargs)
  File "C:\Python27\lib\site-packages\rest_framework\views.py", line 466, in dispatch
    response = self.handle_exception(exc)
  File "C:\Python27\lib\site-packages\rest_framework\views.py", line 463, in dispatch
    response = handler(request, *args, **kwargs)
  File "D:\work\redjango\Management\Cmdb\rests.py", line 28, in post
    ret = Methods.get('POST').get(fun)(request)
  File "D:\work\redjango\Management\Cmdb\methods\cmdb_fun.py", line 134, in group_post
    ret=globals()[request.POST.get('type')](request)
  File "D:\work\redjango\Management\Cmdb\methods\cmdb_fun.py", line 102, in group_update
    ddata=json.loads(request.POST.get('newarray'))
  File "C:\Python27\lib\json\__init__.py", line 339, in loads
    return _default_decoder.decode(s)
  File "C:\Python27\lib\json\decoder.py", line 364, in decode
    obj, end = self.raw_decode(s, idx=_w(s, 0).end())
TypeError: expected string or buffer
[ERROR 2016-11-19 09:30:08,970 @ 26840] (C:\Python27\lib\site-packages\django\core\handlers\base.py/handle_uncaught_exception:256) - Internal Server Error: /v1/cmdb/list/grouppost/
Traceback (most recent call last):
  File "C:\Python27\lib\site-packages\django\core\handlers\base.py", line 132, in get_response
    response = wrapped_callback(request, *callback_args, **callback_kwargs)
  File "C:\Python27\lib\site-packages\django\views\decorators\csrf.py", line 58, in wrapped_view
    return view_func(*args, **kwargs)
  File "C:\Python27\lib\site-packages\django\views\generic\base.py", line 71, in view
    return self.dispatch(request, *args, **kwargs)
  File "C:\Python27\lib\site-packages\rest_framework\views.py", line 466, in dispatch
    response = self.handle_exception(exc)
  File "C:\Python27\lib\site-packages\rest_framework\views.py", line 463, in dispatch
    response = handler(request, *args, **kwargs)
  File "D:\work\redjango\Management\Cmdb\rests.py", line 28, in post
    ret = Methods.get('POST').get(fun)(request)
  File "D:\work\redjango\Management\Cmdb\methods\cmdb_fun.py", line 134, in group_post
    ret=globals()[request.POST.get('type')](request)
  File "D:\work\redjango\Management\Cmdb\methods\cmdb_fun.py", line 102, in group_update
    ddata=json.loads(request.POST.get('newarray',[]))
  File "C:\Python27\lib\json\__init__.py", line 339, in loads
    return _default_decoder.decode(s)
  File "C:\Python27\lib\json\decoder.py", line 364, in decode
    obj, end = self.raw_decode(s, idx=_w(s, 0).end())
TypeError: expected string or buffer
[ERROR 2016-11-19 09:30:43,753 @ 11880] (C:\Python27\lib\site-packages\django\core\handlers\base.py/handle_uncaught_exception:256) - Internal Server Error: /v1/cmdb/list/grouppost/
Traceback (most recent call last):
  File "C:\Python27\lib\site-packages\django\core\handlers\base.py", line 132, in get_response
    response = wrapped_callback(request, *callback_args, **callback_kwargs)
  File "C:\Python27\lib\site-packages\django\views\decorators\csrf.py", line 58, in wrapped_view
    return view_func(*args, **kwargs)
  File "C:\Python27\lib\site-packages\django\views\generic\base.py", line 71, in view
    return self.dispatch(request, *args, **kwargs)
  File "C:\Python27\lib\site-packages\rest_framework\views.py", line 466, in dispatch
    response = self.handle_exception(exc)
  File "C:\Python27\lib\site-packages\rest_framework\views.py", line 463, in dispatch
    response = handler(request, *args, **kwargs)
  File "D:\work\redjango\Management\Cmdb\rests.py", line 28, in post
    ret = Methods.get('POST').get(fun)(request)
  File "D:\work\redjango\Management\Cmdb\methods\cmdb_fun.py", line 134, in group_post
    ret=globals()[request.POST.get('type')](request)
  File "D:\work\redjango\Management\Cmdb\methods\cmdb_fun.py", line 102, in group_update
    ddata=json.loads(request.POST.get('newarray',None))
  File "C:\Python27\lib\json\__init__.py", line 339, in loads
    return _default_decoder.decode(s)
  File "C:\Python27\lib\json\decoder.py", line 364, in decode
    obj, end = self.raw_decode(s, idx=_w(s, 0).end())
TypeError: expected string or buffer
[ERROR 2016-11-19 09:31:09,391 @ 21308] (C:\Python27\lib\site-packages\django\core\handlers\base.py/handle_uncaught_exception:256) - Internal Server Error: /v1/cmdb/list/grouppost/
Traceback (most recent call last):
  File "C:\Python27\lib\site-packages\django\core\handlers\base.py", line 132, in get_response
    response = wrapped_callback(request, *callback_args, **callback_kwargs)
  File "C:\Python27\lib\site-packages\django\views\decorators\csrf.py", line 58, in wrapped_view
    return view_func(*args, **kwargs)
  File "C:\Python27\lib\site-packages\django\views\generic\base.py", line 71, in view
    return self.dispatch(request, *args, **kwargs)
  File "C:\Python27\lib\site-packages\rest_framework\views.py", line 466, in dispatch
    response = self.handle_exception(exc)
  File "C:\Python27\lib\site-packages\rest_framework\views.py", line 463, in dispatch
    response = handler(request, *args, **kwargs)
  File "D:\work\redjango\Management\Cmdb\rests.py", line 28, in post
    ret = Methods.get('POST').get(fun)(request)
  File "D:\work\redjango\Management\Cmdb\methods\cmdb_fun.py", line 134, in group_post
    ret=globals()[request.POST.get('type')](request)
  File "D:\work\redjango\Management\Cmdb\methods\cmdb_fun.py", line 123, in group_update
    ret['status'] = e[1]
IndexError: tuple index out of range
[ERROR 2016-11-19 09:31:22,144 @ 21308] (C:\Python27\lib\site-packages\django\core\handlers\base.py/handle_uncaught_exception:256) - Internal Server Error: /v1/cmdb/list/grouppost/
Traceback (most recent call last):
  File "C:\Python27\lib\site-packages\django\core\handlers\base.py", line 132, in get_response
    response = wrapped_callback(request, *callback_args, **callback_kwargs)
  File "C:\Python27\lib\site-packages\django\views\decorators\csrf.py", line 58, in wrapped_view
    return view_func(*args, **kwargs)
  File "C:\Python27\lib\site-packages\django\views\generic\base.py", line 71, in view
    return self.dispatch(request, *args, **kwargs)
  File "C:\Python27\lib\site-packages\rest_framework\views.py", line 466, in dispatch
    response = self.handle_exception(exc)
  File "C:\Python27\lib\site-packages\rest_framework\views.py", line 463, in dispatch
    response = handler(request, *args, **kwargs)
  File "D:\work\redjango\Management\Cmdb\rests.py", line 28, in post
    ret = Methods.get('POST').get(fun)(request)
  File "D:\work\redjango\Management\Cmdb\methods\cmdb_fun.py", line 134, in group_post
    ret=globals()[request.POST.get('type')](request)
  File "D:\work\redjango\Management\Cmdb\methods\cmdb_fun.py", line 123, in group_update
    ret['status'] = e[1]
IndexError: tuple index out of range
[ERROR 2016-11-19 09:31:50,973 @ 22504] (C:\Python27\lib\site-packages\django\core\handlers\base.py/handle_uncaught_exception:256) - Internal Server Error: /v1/cmdb/list/grouppost/
Traceback (most recent call last):
  File "C:\Python27\lib\site-packages\django\core\handlers\base.py", line 132, in get_response
    response = wrapped_callback(request, *callback_args, **callback_kwargs)
  File "C:\Python27\lib\site-packages\django\views\decorators\csrf.py", line 58, in wrapped_view
    return view_func(*args, **kwargs)
  File "C:\Python27\lib\site-packages\django\views\generic\base.py", line 71, in view
    return self.dispatch(request, *args, **kwargs)
  File "C:\Python27\lib\site-packages\rest_framework\views.py", line 466, in dispatch
    response = self.handle_exception(exc)
  File "C:\Python27\lib\site-packages\rest_framework\views.py", line 463, in dispatch
    response = handler(request, *args, **kwargs)
  File "D:\work\redjango\Management\Cmdb\rests.py", line 28, in post
    ret = Methods.get('POST').get(fun)(request)
  File "D:\work\redjango\Management\Cmdb\methods\cmdb_fun.py", line 135, in group_post
    ret=globals()[request.POST.get('type')](request)
  File "D:\work\redjango\Management\Cmdb\methods\cmdb_fun.py", line 124, in group_update
    ret['status'] = e[1]
IndexError: tuple index out of range
[ERROR 2016-11-19 09:32:34,618 @ 19624] (C:\Python27\lib\site-packages\django\core\handlers\base.py/handle_uncaught_exception:256) - Internal Server Error: /v1/cmdb/list/grouppost/
Traceback (most recent call last):
  File "C:\Python27\lib\site-packages\django\core\handlers\base.py", line 132, in get_response
    response = wrapped_callback(request, *callback_args, **callback_kwargs)
  File "C:\Python27\lib\site-packages\django\views\decorators\csrf.py", line 58, in wrapped_view
    return view_func(*args, **kwargs)
  File "C:\Python27\lib\site-packages\django\views\generic\base.py", line 71, in view
    return self.dispatch(request, *args, **kwargs)
  File "C:\Python27\lib\site-packages\rest_framework\views.py", line 466, in dispatch
    response = self.handle_exception(exc)
  File "C:\Python27\lib\site-packages\rest_framework\views.py", line 463, in dispatch
    response = handler(request, *args, **kwargs)
  File "D:\work\redjango\Management\Cmdb\rests.py", line 28, in post
    ret = Methods.get('POST').get(fun)(request)
  File "D:\work\redjango\Management\Cmdb\methods\cmdb_fun.py", line 135, in group_post
    ret=globals()[request.POST.get('type')](request)
  File "D:\work\redjango\Management\Cmdb\methods\cmdb_fun.py", line 124, in group_update
    ret['status'] = e[1]
IndexError: tuple index out of range
[ERROR 2016-11-19 09:33:49,915 @ 21384] (C:\Python27\lib\site-packages\django\core\handlers\base.py/handle_uncaught_exception:256) - Internal Server Error: /v1/cmdb/list/grouppost/
Traceback (most recent call last):
  File "C:\Python27\lib\site-packages\django\core\handlers\base.py", line 132, in get_response
    response = wrapped_callback(request, *callback_args, **callback_kwargs)
  File "C:\Python27\lib\site-packages\django\views\decorators\csrf.py", line 58, in wrapped_view
    return view_func(*args, **kwargs)
  File "C:\Python27\lib\site-packages\django\views\generic\base.py", line 71, in view
    return self.dispatch(request, *args, **kwargs)
  File "C:\Python27\lib\site-packages\rest_framework\views.py", line 466, in dispatch
    response = self.handle_exception(exc)
  File "C:\Python27\lib\site-packages\rest_framework\views.py", line 463, in dispatch
    response = handler(request, *args, **kwargs)
  File "D:\work\redjango\Management\Cmdb\rests.py", line 29, in post
    return packageResponse(ret)
  File "D:\work\redjango\Management\Cmdb\methods\common.py", line 12, in packageResponse
    json_status = json.dumps(json_status)
  File "C:\Python27\lib\json\__init__.py", line 244, in dumps
    return _default_encoder.encode(obj)
  File "C:\Python27\lib\json\encoder.py", line 207, in encode
    chunks = self.iterencode(o, _one_shot=True)
  File "C:\Python27\lib\json\encoder.py", line 270, in iterencode
    return _iterencode(o, 0)
  File "C:\Python27\lib\json\encoder.py", line 184, in default
    raise TypeError(repr(o) + " is not JSON serializable")
TypeError: AttributeError("'AssetGroup' object has no attribute 'update'",) is not JSON serializable
[ERROR 2016-11-19 10:18:08,982 @ 6952] (C:\Python27\lib\site-packages\django\core\handlers\base.py/handle_uncaught_exception:256) - Internal Server Error: /v1/cmdb/list/grouppost/
Traceback (most recent call last):
  File "C:\Python27\lib\site-packages\django\core\handlers\base.py", line 132, in get_response
    response = wrapped_callback(request, *callback_args, **callback_kwargs)
  File "C:\Python27\lib\site-packages\django\views\decorators\csrf.py", line 58, in wrapped_view
    return view_func(*args, **kwargs)
  File "C:\Python27\lib\site-packages\django\views\generic\base.py", line 71, in view
    return self.dispatch(request, *args, **kwargs)
  File "C:\Python27\lib\site-packages\rest_framework\views.py", line 466, in dispatch
    response = self.handle_exception(exc)
  File "C:\Python27\lib\site-packages\rest_framework\views.py", line 463, in dispatch
    response = handler(request, *args, **kwargs)
  File "D:\work\redjango\Management\Cmdb\rests.py", line 29, in post
    return packageResponse(ret)
  File "D:\work\redjango\Management\Cmdb\methods\common.py", line 12, in packageResponse
    json_status = json.dumps(json_status)
  File "C:\Python27\lib\json\__init__.py", line 244, in dumps
    return _default_encoder.encode(obj)
  File "C:\Python27\lib\json\encoder.py", line 207, in encode
    chunks = self.iterencode(o, _one_shot=True)
  File "C:\Python27\lib\json\encoder.py", line 270, in iterencode
    return _iterencode(o, 0)
  File "C:\Python27\lib\json\encoder.py", line 184, in default
    raise TypeError(repr(o) + " is not JSON serializable")
TypeError: AttributeError("'AssetGroup' object has no attribute 'update'",) is not JSON serializable
[ERROR 2016-11-19 10:18:25,980 @ 6952] (C:\Python27\lib\site-packages\django\core\handlers\base.py/handle_uncaught_exception:256) - Internal Server Error: /v1/cmdb/list/grouppost/
Traceback (most recent call last):
  File "C:\Python27\lib\site-packages\django\core\handlers\base.py", line 132, in get_response
    response = wrapped_callback(request, *callback_args, **callback_kwargs)
  File "C:\Python27\lib\site-packages\django\views\decorators\csrf.py", line 58, in wrapped_view
    return view_func(*args, **kwargs)
  File "C:\Python27\lib\site-packages\django\views\generic\base.py", line 71, in view
    return self.dispatch(request, *args, **kwargs)
  File "C:\Python27\lib\site-packages\rest_framework\views.py", line 466, in dispatch
    response = self.handle_exception(exc)
  File "C:\Python27\lib\site-packages\rest_framework\views.py", line 463, in dispatch
    response = handler(request, *args, **kwargs)
  File "D:\work\redjango\Management\Cmdb\rests.py", line 29, in post
    return packageResponse(ret)
  File "D:\work\redjango\Management\Cmdb\methods\common.py", line 12, in packageResponse
    json_status = json.dumps(json_status)
  File "C:\Python27\lib\json\__init__.py", line 244, in dumps
    return _default_encoder.encode(obj)
  File "C:\Python27\lib\json\encoder.py", line 207, in encode
    chunks = self.iterencode(o, _one_shot=True)
  File "C:\Python27\lib\json\encoder.py", line 270, in iterencode
    return _iterencode(o, 0)
  File "C:\Python27\lib\json\encoder.py", line 184, in default
    raise TypeError(repr(o) + " is not JSON serializable")
TypeError: AttributeError("'AssetGroup' object has no attribute 'update'",) is not JSON serializable
[ERROR 2016-11-19 10:18:28,275 @ 6952] (C:\Python27\lib\site-packages\django\core\handlers\base.py/handle_uncaught_exception:256) - Internal Server Error: /v1/cmdb/list/grouppost/
Traceback (most recent call last):
  File "C:\Python27\lib\site-packages\django\core\handlers\base.py", line 132, in get_response
    response = wrapped_callback(request, *callback_args, **callback_kwargs)
  File "C:\Python27\lib\site-packages\django\views\decorators\csrf.py", line 58, in wrapped_view
    return view_func(*args, **kwargs)
  File "C:\Python27\lib\site-packages\django\views\generic\base.py", line 71, in view
    return self.dispatch(request, *args, **kwargs)
  File "C:\Python27\lib\site-packages\rest_framework\views.py", line 466, in dispatch
    response = self.handle_exception(exc)
  File "C:\Python27\lib\site-packages\rest_framework\views.py", line 463, in dispatch
    response = handler(request, *args, **kwargs)
  File "D:\work\redjango\Management\Cmdb\rests.py", line 29, in post
    return packageResponse(ret)
  File "D:\work\redjango\Management\Cmdb\methods\common.py", line 12, in packageResponse
    json_status = json.dumps(json_status)
  File "C:\Python27\lib\json\__init__.py", line 244, in dumps
    return _default_encoder.encode(obj)
  File "C:\Python27\lib\json\encoder.py", line 207, in encode
    chunks = self.iterencode(o, _one_shot=True)
  File "C:\Python27\lib\json\encoder.py", line 270, in iterencode
    return _iterencode(o, 0)
  File "C:\Python27\lib\json\encoder.py", line 184, in default
    raise TypeError(repr(o) + " is not JSON serializable")
TypeError: AttributeError("'AssetGroup' object has no attribute 'update'",) is not JSON serializable
[ERROR 2016-11-19 10:18:30,923 @ 6952] (C:\Python27\lib\site-packages\django\core\handlers\base.py/handle_uncaught_exception:256) - Internal Server Error: /v1/cmdb/list/grouppost/
Traceback (most recent call last):
  File "C:\Python27\lib\site-packages\django\core\handlers\base.py", line 132, in get_response
    response = wrapped_callback(request, *callback_args, **callback_kwargs)
  File "C:\Python27\lib\site-packages\django\views\decorators\csrf.py", line 58, in wrapped_view
    return view_func(*args, **kwargs)
  File "C:\Python27\lib\site-packages\django\views\generic\base.py", line 71, in view
    return self.dispatch(request, *args, **kwargs)
  File "C:\Python27\lib\site-packages\rest_framework\views.py", line 466, in dispatch
    response = self.handle_exception(exc)
  File "C:\Python27\lib\site-packages\rest_framework\views.py", line 463, in dispatch
    response = handler(request, *args, **kwargs)
  File "D:\work\redjango\Management\Cmdb\rests.py", line 29, in post
    return packageResponse(ret)
  File "D:\work\redjango\Management\Cmdb\methods\common.py", line 12, in packageResponse
    json_status = json.dumps(json_status)
  File "C:\Python27\lib\json\__init__.py", line 244, in dumps
    return _default_encoder.encode(obj)
  File "C:\Python27\lib\json\encoder.py", line 207, in encode
    chunks = self.iterencode(o, _one_shot=True)
  File "C:\Python27\lib\json\encoder.py", line 270, in iterencode
    return _iterencode(o, 0)
  File "C:\Python27\lib\json\encoder.py", line 184, in default
    raise TypeError(repr(o) + " is not JSON serializable")
TypeError: AttributeError("'AssetGroup' object has no attribute 'update'",) is not JSON serializable
[ERROR 2016-11-19 10:18:34,153 @ 6952] (C:\Python27\lib\site-packages\django\core\handlers\base.py/handle_uncaught_exception:256) - Internal Server Error: /v1/cmdb/list/grouppost/
Traceback (most recent call last):
  File "C:\Python27\lib\site-packages\django\core\handlers\base.py", line 132, in get_response
    response = wrapped_callback(request, *callback_args, **callback_kwargs)
  File "C:\Python27\lib\site-packages\django\views\decorators\csrf.py", line 58, in wrapped_view
    return view_func(*args, **kwargs)
  File "C:\Python27\lib\site-packages\django\views\generic\base.py", line 71, in view
    return self.dispatch(request, *args, **kwargs)
  File "C:\Python27\lib\site-packages\rest_framework\views.py", line 466, in dispatch
    response = self.handle_exception(exc)
  File "C:\Python27\lib\site-packages\rest_framework\views.py", line 463, in dispatch
    response = handler(request, *args, **kwargs)
  File "D:\work\redjango\Management\Cmdb\rests.py", line 24, in get
    ret = Methods.get('GET').get(fun)(request)
TypeError: 'NoneType' object is not callable
[ERROR 2016-11-19 10:19:23,802 @ 14960] (C:\Python27\lib\site-packages\django\core\handlers\base.py/handle_uncaught_exception:256) - Internal Server Error: /v1/cmdb/list/grouppost/
Traceback (most recent call last):
  File "C:\Python27\lib\site-packages\django\core\handlers\base.py", line 132, in get_response
    response = wrapped_callback(request, *callback_args, **callback_kwargs)
  File "C:\Python27\lib\site-packages\django\views\decorators\csrf.py", line 58, in wrapped_view
    return view_func(*args, **kwargs)
  File "C:\Python27\lib\site-packages\django\views\generic\base.py", line 71, in view
    return self.dispatch(request, *args, **kwargs)
  File "C:\Python27\lib\site-packages\rest_framework\views.py", line 466, in dispatch
    response = self.handle_exception(exc)
  File "C:\Python27\lib\site-packages\rest_framework\views.py", line 463, in dispatch
    response = handler(request, *args, **kwargs)
  File "D:\work\redjango\Management\Cmdb\rests.py", line 24, in get
    ret = Methods.get('GET').get(fun)(request)
TypeError: 'NoneType' object is not callable
[ERROR 2016-11-19 10:19:38,806 @ 14960] (C:\Python27\lib\site-packages\django\core\handlers\base.py/handle_uncaught_exception:256) - Internal Server Error: /v1/cmdb/list/grouppost/
Traceback (most recent call last):
  File "C:\Python27\lib\site-packages\django\core\handlers\base.py", line 132, in get_response
    response = wrapped_callback(request, *callback_args, **callback_kwargs)
  File "C:\Python27\lib\site-packages\django\views\decorators\csrf.py", line 58, in wrapped_view
    return view_func(*args, **kwargs)
  File "C:\Python27\lib\site-packages\django\views\generic\base.py", line 71, in view
    return self.dispatch(request, *args, **kwargs)
  File "C:\Python27\lib\site-packages\rest_framework\views.py", line 466, in dispatch
    response = self.handle_exception(exc)
  File "C:\Python27\lib\site-packages\rest_framework\views.py", line 463, in dispatch
    response = handler(request, *args, **kwargs)
  File "D:\work\redjango\Management\Cmdb\rests.py", line 29, in post
    return packageResponse(ret)
  File "D:\work\redjango\Management\Cmdb\methods\common.py", line 12, in packageResponse
    json_status = json.dumps(json_status)
  File "C:\Python27\lib\json\__init__.py", line 244, in dumps
    return _default_encoder.encode(obj)
  File "C:\Python27\lib\json\encoder.py", line 207, in encode
    chunks = self.iterencode(o, _one_shot=True)
  File "C:\Python27\lib\json\encoder.py", line 270, in iterencode
    return _iterencode(o, 0)
  File "C:\Python27\lib\json\encoder.py", line 184, in default
    raise TypeError(repr(o) + " is not JSON serializable")
TypeError: AttributeError("'AssetGroup' object has no attribute 'update'",) is not JSON serializable
[ERROR 2016-11-19 10:34:29,825 @ 27300] (C:\Python27\lib\site-packages\django\core\handlers\base.py/handle_uncaught_exception:256) - Internal Server Error: /v1/cmdb/list/grouppost/
Traceback (most recent call last):
  File "C:\Python27\lib\site-packages\django\core\handlers\base.py", line 132, in get_response
    response = wrapped_callback(request, *callback_args, **callback_kwargs)
  File "C:\Python27\lib\site-packages\django\views\decorators\csrf.py", line 58, in wrapped_view
    return view_func(*args, **kwargs)
  File "C:\Python27\lib\site-packages\django\views\generic\base.py", line 71, in view
    return self.dispatch(request, *args, **kwargs)
  File "C:\Python27\lib\site-packages\rest_framework\views.py", line 466, in dispatch
    response = self.handle_exception(exc)
  File "C:\Python27\lib\site-packages\rest_framework\views.py", line 463, in dispatch
    response = handler(request, *args, **kwargs)
  File "D:\work\redjango\Management\Cmdb\rests.py", line 28, in post
    ret = Methods.get('POST').get(fun)(request)
  File "D:\work\redjango\Management\Cmdb\methods\cmdb_fun.py", line 140, in group_post
    ret=globals()[request.POST.get('type')](request)
  File "D:\work\redjango\Management\Cmdb\methods\cmdb_fun.py", line 102, in group_update
    ddata=json.loads(request.POST.get('newarray'))
  File "C:\Python27\lib\json\__init__.py", line 339, in loads
    return _default_decoder.decode(s)
  File "C:\Python27\lib\json\decoder.py", line 364, in decode
    obj, end = self.raw_decode(s, idx=_w(s, 0).end())
TypeError: expected string or buffer
[ERROR 2016-11-19 10:34:58,655 @ 27300] (C:\Python27\lib\site-packages\django\core\handlers\base.py/handle_uncaught_exception:256) - Internal Server Error: /v1/cmdb/list/grouppost/
Traceback (most recent call last):
  File "C:\Python27\lib\site-packages\django\core\handlers\base.py", line 132, in get_response
    response = wrapped_callback(request, *callback_args, **callback_kwargs)
  File "C:\Python27\lib\site-packages\django\views\decorators\csrf.py", line 58, in wrapped_view
    return view_func(*args, **kwargs)
  File "C:\Python27\lib\site-packages\django\views\generic\base.py", line 71, in view
    return self.dispatch(request, *args, **kwargs)
  File "C:\Python27\lib\site-packages\rest_framework\views.py", line 466, in dispatch
    response = self.handle_exception(exc)
  File "C:\Python27\lib\site-packages\rest_framework\views.py", line 463, in dispatch
    response = handler(request, *args, **kwargs)
  File "D:\work\redjango\Management\Cmdb\rests.py", line 29, in post
    return packageResponse(ret)
  File "D:\work\redjango\Management\Cmdb\methods\common.py", line 12, in packageResponse
    json_status = json.dumps(json_status)
  File "C:\Python27\lib\json\__init__.py", line 244, in dumps
    return _default_encoder.encode(obj)
  File "C:\Python27\lib\json\encoder.py", line 207, in encode
    chunks = self.iterencode(o, _one_shot=True)
  File "C:\Python27\lib\json\encoder.py", line 270, in iterencode
    return _iterencode(o, 0)
  File "C:\Python27\lib\json\encoder.py", line 184, in default
    raise TypeError(repr(o) + " is not JSON serializable")
TypeError: AttributeError("'AssetGroup' object has no attribute 'update'",) is not JSON serializable
[ERROR 2016-11-19 10:36:54,194 @ 9308] (C:\Python27\lib\site-packages\django\core\handlers\base.py/handle_uncaught_exception:256) - Internal Server Error: /v1/cmdb/list/grouppost/
Traceback (most recent call last):
  File "C:\Python27\lib\site-packages\django\core\handlers\base.py", line 132, in get_response
    response = wrapped_callback(request, *callback_args, **callback_kwargs)
  File "C:\Python27\lib\site-packages\django\views\decorators\csrf.py", line 58, in wrapped_view
    return view_func(*args, **kwargs)
  File "C:\Python27\lib\site-packages\django\views\generic\base.py", line 71, in view
    return self.dispatch(request, *args, **kwargs)
  File "C:\Python27\lib\site-packages\rest_framework\views.py", line 466, in dispatch
    response = self.handle_exception(exc)
  File "C:\Python27\lib\site-packages\rest_framework\views.py", line 463, in dispatch
    response = handler(request, *args, **kwargs)
  File "D:\work\redjango\Management\Cmdb\rests.py", line 28, in post
    ret = Methods.get('POST').get(fun)(request)
  File "D:\work\redjango\Management\Cmdb\methods\cmdb_fun.py", line 140, in group_post
    ret=globals()[request.POST.get('type')](request)
  File "D:\work\redjango\Management\Cmdb\methods\cmdb_fun.py", line 102, in group_update
    ddata=json.loads(request.POST.get('newarray'))
  File "C:\Python27\lib\json\__init__.py", line 339, in loads
    return _default_decoder.decode(s)
  File "C:\Python27\lib\json\decoder.py", line 364, in decode
    obj, end = self.raw_decode(s, idx=_w(s, 0).end())
TypeError: expected string or buffer
[ERROR 2016-11-19 11:15:42,801 @ 11024] (C:\Python27\lib\site-packages\django\core\handlers\base.py/handle_uncaught_exception:256) - Internal Server Error: /v1/cmdb/list/assetpost/
Traceback (most recent call last):
  File "C:\Python27\lib\site-packages\django\core\handlers\base.py", line 132, in get_response
    response = wrapped_callback(request, *callback_args, **callback_kwargs)
  File "C:\Python27\lib\site-packages\django\views\decorators\csrf.py", line 58, in wrapped_view
    return view_func(*args, **kwargs)
  File "C:\Python27\lib\site-packages\django\views\generic\base.py", line 71, in view
    return self.dispatch(request, *args, **kwargs)
  File "C:\Python27\lib\site-packages\rest_framework\views.py", line 466, in dispatch
    response = self.handle_exception(exc)
  File "C:\Python27\lib\site-packages\rest_framework\views.py", line 463, in dispatch
    response = handler(request, *args, **kwargs)
  File "D:\work\redjango\Management\Cmdb\rests.py", line 28, in post
    ret = Methods.get('POST').get(fun)(request)
  File "D:\work\redjango\Management\Cmdb\methods\cmdb_fun.py", line 186, in assetpost
    ret['status'] = e[1]
IndexError: tuple index out of range
[ERROR 2016-11-19 14:23:24,176 @ 9676] (C:\Python27\lib\site-packages\django\core\handlers\base.py/handle_uncaught_exception:256) - Internal Server Error: /v1/cmdb/list/groupget/
Traceback (most recent call last):
  File "C:\Python27\lib\site-packages\django\core\handlers\base.py", line 132, in get_response
    response = wrapped_callback(request, *callback_args, **callback_kwargs)
  File "C:\Python27\lib\site-packages\django\views\decorators\csrf.py", line 58, in wrapped_view
    return view_func(*args, **kwargs)
  File "C:\Python27\lib\site-packages\django\views\generic\base.py", line 71, in view
    return self.dispatch(request, *args, **kwargs)
  File "C:\Python27\lib\site-packages\rest_framework\views.py", line 466, in dispatch
    response = self.handle_exception(exc)
  File "C:\Python27\lib\site-packages\rest_framework\views.py", line 463, in dispatch
    response = handler(request, *args, **kwargs)
  File "D:\work\redjango\Management\Cmdb\rests.py", line 24, in get
    ret = Methods.get('GET').get(fun)(request)
  File "D:\work\redjango\Management\Cmdb\methods\cmdb_fun.py", line 77, in group_get
    ret['data']=globals()[request.GET.get('name')](group_id)
KeyError: None
[ERROR 2016-11-22 10:58:00,253 @ 9676] (C:\Python27\lib\site-packages\django\core\handlers\base.py/handle_uncaught_exception:256) - Internal Server Error: /v1/cmdb/list/groupget/
Traceback (most recent call last):
  File "C:\Python27\lib\site-packages\django\core\handlers\base.py", line 132, in get_response
    response = wrapped_callback(request, *callback_args, **callback_kwargs)
  File "C:\Python27\lib\site-packages\django\views\decorators\csrf.py", line 58, in wrapped_view
    return view_func(*args, **kwargs)
  File "C:\Python27\lib\site-packages\django\views\generic\base.py", line 71, in view
    return self.dispatch(request, *args, **kwargs)
  File "C:\Python27\lib\site-packages\rest_framework\views.py", line 466, in dispatch
    response = self.handle_exception(exc)
  File "C:\Python27\lib\site-packages\rest_framework\views.py", line 463, in dispatch
    response = handler(request, *args, **kwargs)
  File "D:\work\redjango\Management\Cmdb\rests.py", line 24, in get
    ret = Methods.get('GET').get(fun)(request)
  File "D:\work\redjango\Management\Cmdb\methods\cmdb_fun.py", line 77, in group_get
    ret['data']=globals()[request.GET.get('name')](group_id)
KeyError: None
[ERROR 2016-11-24 10:21:40,322 @ 7936] (C:\Python27\lib\site-packages\django\core\handlers\base.py/handle_uncaught_exception:256) - Internal Server Error: /v1/cmdb/list/groupget/
Traceback (most recent call last):
  File "C:\Python27\lib\site-packages\django\core\handlers\base.py", line 132, in get_response
    response = wrapped_callback(request, *callback_args, **callback_kwargs)
  File "C:\Python27\lib\site-packages\django\views\decorators\csrf.py", line 58, in wrapped_view
    return view_func(*args, **kwargs)
  File "C:\Python27\lib\site-packages\django\views\generic\base.py", line 71, in view
    return self.dispatch(request, *args, **kwargs)
  File "C:\Python27\lib\site-packages\rest_framework\views.py", line 466, in dispatch
    response = self.handle_exception(exc)
  File "C:\Python27\lib\site-packages\rest_framework\views.py", line 463, in dispatch
    response = handler(request, *args, **kwargs)
  File "D:\work\redjango\Management\Cmdb\rests.py", line 24, in get
    ret = Methods.get('GET').get(fun)(request)
  File "D:\work\redjango\Management\Cmdb\methods\cmdb_fun.py", line 77, in group_get
    ret['data']=globals()[request.GET.get('name')](group_id)
KeyError: None
[ERROR 2016-11-24 10:35:42,640 @ 8188] (C:\Python27\lib\site-packages\django\core\handlers\base.py/handle_uncaught_exception:256) - Internal Server Error: /v1/cmdb/list/groupget/
Traceback (most recent call last):
  File "C:\Python27\lib\site-packages\django\core\handlers\base.py", line 132, in get_response
    response = wrapped_callback(request, *callback_args, **callback_kwargs)
  File "C:\Python27\lib\site-packages\django\views\decorators\csrf.py", line 58, in wrapped_view
    return view_func(*args, **kwargs)
  File "C:\Python27\lib\site-packages\django\views\generic\base.py", line 71, in view
    return self.dispatch(request, *args, **kwargs)
  File "C:\Python27\lib\site-packages\rest_framework\views.py", line 466, in dispatch
    response = self.handle_exception(exc)
  File "C:\Python27\lib\site-packages\rest_framework\views.py", line 463, in dispatch
    response = handler(request, *args, **kwargs)
  File "D:\work\redjango\Management\Cmdb\rests.py", line 24, in get
    ret = Methods.get('GET').get(fun)(request)
  File "D:\work\redjango\Management\Cmdb\methods\cmdb_fun.py", line 77, in group_get
    ret['data']=globals()[request.GET.get('name')](group_id)
KeyError: None
[ERROR 2016-11-24 10:43:34,006 @ 1264] (C:\Python27\lib\site-packages\django\core\handlers\base.py/handle_uncaught_exception:256) - Internal Server Error: /v1/cmdb/list/groupget/
Traceback (most recent call last):
  File "C:\Python27\lib\site-packages\django\core\handlers\base.py", line 132, in get_response
    response = wrapped_callback(request, *callback_args, **callback_kwargs)
  File "C:\Python27\lib\site-packages\django\views\decorators\csrf.py", line 58, in wrapped_view
    return view_func(*args, **kwargs)
  File "C:\Python27\lib\site-packages\django\views\generic\base.py", line 71, in view
    return self.dispatch(request, *args, **kwargs)
  File "C:\Python27\lib\site-packages\rest_framework\views.py", line 466, in dispatch
    response = self.handle_exception(exc)
  File "C:\Python27\lib\site-packages\rest_framework\views.py", line 463, in dispatch
    response = handler(request, *args, **kwargs)
  File "D:\work\redjango\Management\Cmdb\rests.py", line 24, in get
    ret = Methods.get('GET').get(fun)(request)
  File "D:\work\redjango\Management\Cmdb\methods\cmdb_fun.py", line 77, in group_get
    ret['data']=globals()[request.GET.get('name')](group_id)
KeyError: None
[ERROR 2016-11-24 15:03:02,487 @ 1264] (C:\Python27\lib\site-packages\django\core\handlers\base.py/handle_uncaught_exception:256) - Internal Server Error: /v1/cmdb/list/groupget/
Traceback (most recent call last):
  File "C:\Python27\lib\site-packages\django\core\handlers\base.py", line 132, in get_response
    response = wrapped_callback(request, *callback_args, **callback_kwargs)
  File "C:\Python27\lib\site-packages\django\views\decorators\csrf.py", line 58, in wrapped_view
    return view_func(*args, **kwargs)
  File "C:\Python27\lib\site-packages\django\views\generic\base.py", line 71, in view
    return self.dispatch(request, *args, **kwargs)
  File "C:\Python27\lib\site-packages\rest_framework\views.py", line 466, in dispatch
    response = self.handle_exception(exc)
  File "C:\Python27\lib\site-packages\rest_framework\views.py", line 463, in dispatch
    response = handler(request, *args, **kwargs)
  File "D:\work\redjango\Management\Cmdb\rests.py", line 24, in get
    ret = Methods.get('GET').get(fun)(request)
  File "D:\work\redjango\Management\Cmdb\methods\cmdb_fun.py", line 77, in group_get
    ret['data']=globals()[request.GET.get('name')](group_id)
KeyError: None
[ERROR 2016-11-24 15:03:42,270 @ 1264] (C:\Python27\lib\site-packages\django\core\handlers\base.py/handle_uncaught_exception:256) - Internal Server Error: /v1/cmdb/list/groupget/
Traceback (most recent call last):
  File "C:\Python27\lib\site-packages\django\core\handlers\base.py", line 132, in get_response
    response = wrapped_callback(request, *callback_args, **callback_kwargs)
  File "C:\Python27\lib\site-packages\django\views\decorators\csrf.py", line 58, in wrapped_view
    return view_func(*args, **kwargs)
  File "C:\Python27\lib\site-packages\django\views\generic\base.py", line 71, in view
    return self.dispatch(request, *args, **kwargs)
  File "C:\Python27\lib\site-packages\rest_framework\views.py", line 466, in dispatch
    response = self.handle_exception(exc)
  File "C:\Python27\lib\site-packages\rest_framework\views.py", line 463, in dispatch
    response = handler(request, *args, **kwargs)
  File "D:\work\redjango\Management\Cmdb\rests.py", line 24, in get
    ret = Methods.get('GET').get(fun)(request)
  File "D:\work\redjango\Management\Cmdb\methods\cmdb_fun.py", line 77, in group_get
    ret['data']=globals()[request.GET.get('name')](group_id)
KeyError: None
[ERROR 2016-11-24 15:03:46,026 @ 1264] (C:\Python27\lib\site-packages\django\core\handlers\base.py/handle_uncaught_exception:256) - Internal Server Error: /v1/cmdb/list/groupget/
Traceback (most recent call last):
  File "C:\Python27\lib\site-packages\django\core\handlers\base.py", line 132, in get_response
    response = wrapped_callback(request, *callback_args, **callback_kwargs)
  File "C:\Python27\lib\site-packages\django\views\decorators\csrf.py", line 58, in wrapped_view
    return view_func(*args, **kwargs)
  File "C:\Python27\lib\site-packages\django\views\generic\base.py", line 71, in view
    return self.dispatch(request, *args, **kwargs)
  File "C:\Python27\lib\site-packages\rest_framework\views.py", line 466, in dispatch
    response = self.handle_exception(exc)
  File "C:\Python27\lib\site-packages\rest_framework\views.py", line 463, in dispatch
    response = handler(request, *args, **kwargs)
  File "D:\work\redjango\Management\Cmdb\rests.py", line 24, in get
    ret = Methods.get('GET').get(fun)(request)
  File "D:\work\redjango\Management\Cmdb\methods\cmdb_fun.py", line 77, in group_get
    ret['data']=globals()[request.GET.get('name')](group_id)
KeyError: None
[ERROR 2016-11-24 15:04:05,433 @ 1264] (C:\Python27\lib\site-packages\django\core\handlers\base.py/handle_uncaught_exception:256) - Internal Server Error: /v1/cmdb/list/groupget/
Traceback (most recent call last):
  File "C:\Python27\lib\site-packages\django\core\handlers\base.py", line 132, in get_response
    response = wrapped_callback(request, *callback_args, **callback_kwargs)
  File "C:\Python27\lib\site-packages\django\views\decorators\csrf.py", line 58, in wrapped_view
    return view_func(*args, **kwargs)
  File "C:\Python27\lib\site-packages\django\views\generic\base.py", line 71, in view
    return self.dispatch(request, *args, **kwargs)
  File "C:\Python27\lib\site-packages\rest_framework\views.py", line 466, in dispatch
    response = self.handle_exception(exc)
  File "C:\Python27\lib\site-packages\rest_framework\views.py", line 463, in dispatch
    response = handler(request, *args, **kwargs)
  File "D:\work\redjango\Management\Cmdb\rests.py", line 24, in get
    ret = Methods.get('GET').get(fun)(request)
  File "D:\work\redjango\Management\Cmdb\methods\cmdb_fun.py", line 77, in group_get
    ret['data']=globals()[request.GET.get('name')](group_id)
KeyError: None
[ERROR 2016-11-24 15:04:12,539 @ 1264] (C:\Python27\lib\site-packages\django\core\handlers\base.py/handle_uncaught_exception:256) - Internal Server Error: /v1/cmdb/list/groupget/
Traceback (most recent call last):
  File "C:\Python27\lib\site-packages\django\core\handlers\base.py", line 132, in get_response
    response = wrapped_callback(request, *callback_args, **callback_kwargs)
  File "C:\Python27\lib\site-packages\django\views\decorators\csrf.py", line 58, in wrapped_view
    return view_func(*args, **kwargs)
  File "C:\Python27\lib\site-packages\django\views\generic\base.py", line 71, in view
    return self.dispatch(request, *args, **kwargs)
  File "C:\Python27\lib\site-packages\rest_framework\views.py", line 466, in dispatch
    response = self.handle_exception(exc)
  File "C:\Python27\lib\site-packages\rest_framework\views.py", line 463, in dispatch
    response = handler(request, *args, **kwargs)
  File "D:\work\redjango\Management\Cmdb\rests.py", line 24, in get
    ret = Methods.get('GET').get(fun)(request)
  File "D:\work\redjango\Management\Cmdb\methods\cmdb_fun.py", line 77, in group_get
    ret['data']=globals()[request.GET.get('name')](group_id)
KeyError: None
[ERROR 2016-11-24 15:04:38,523 @ 1264] (C:\Python27\lib\site-packages\django\core\handlers\base.py/handle_uncaught_exception:256) - Internal Server Error: /v1/cmdb/list/groupget/
Traceback (most recent call last):
  File "C:\Python27\lib\site-packages\django\core\handlers\base.py", line 132, in get_response
    response = wrapped_callback(request, *callback_args, **callback_kwargs)
  File "C:\Python27\lib\site-packages\django\views\decorators\csrf.py", line 58, in wrapped_view
    return view_func(*args, **kwargs)
  File "C:\Python27\lib\site-packages\django\views\generic\base.py", line 71, in view
    return self.dispatch(request, *args, **kwargs)
  File "C:\Python27\lib\site-packages\rest_framework\views.py", line 466, in dispatch
    response = self.handle_exception(exc)
  File "C:\Python27\lib\site-packages\rest_framework\views.py", line 463, in dispatch
    response = handler(request, *args, **kwargs)
  File "D:\work\redjango\Management\Cmdb\rests.py", line 24, in get
    ret = Methods.get('GET').get(fun)(request)
  File "D:\work\redjango\Management\Cmdb\methods\cmdb_fun.py", line 77, in group_get
    ret['data']=globals()[request.GET.get('name')](group_id)
KeyError: None
[ERROR 2016-11-24 15:04:41,062 @ 1264] (C:\Python27\lib\site-packages\django\core\handlers\base.py/handle_uncaught_exception:256) - Internal Server Error: /v1/cmdb/list/groupget/
Traceback (most recent call last):
  File "C:\Python27\lib\site-packages\django\core\handlers\base.py", line 132, in get_response
    response = wrapped_callback(request, *callback_args, **callback_kwargs)
  File "C:\Python27\lib\site-packages\django\views\decorators\csrf.py", line 58, in wrapped_view
    return view_func(*args, **kwargs)
  File "C:\Python27\lib\site-packages\django\views\generic\base.py", line 71, in view
    return self.dispatch(request, *args, **kwargs)
  File "C:\Python27\lib\site-packages\rest_framework\views.py", line 466, in dispatch
    response = self.handle_exception(exc)
  File "C:\Python27\lib\site-packages\rest_framework\views.py", line 463, in dispatch
    response = handler(request, *args, **kwargs)
  File "D:\work\redjango\Management\Cmdb\rests.py", line 24, in get
    ret = Methods.get('GET').get(fun)(request)
  File "D:\work\redjango\Management\Cmdb\methods\cmdb_fun.py", line 77, in group_get
    ret['data']=globals()[request.GET.get('name')](group_id)
KeyError: None
[ERROR 2016-11-24 15:04:58,108 @ 1264] (C:\Python27\lib\site-packages\django\core\handlers\base.py/handle_uncaught_exception:256) - Internal Server Error: /v1/cmdb/list/groupget/
Traceback (most recent call last):
  File "C:\Python27\lib\site-packages\django\core\handlers\base.py", line 132, in get_response
    response = wrapped_callback(request, *callback_args, **callback_kwargs)
  File "C:\Python27\lib\site-packages\django\views\decorators\csrf.py", line 58, in wrapped_view
    return view_func(*args, **kwargs)
  File "C:\Python27\lib\site-packages\django\views\generic\base.py", line 71, in view
    return self.dispatch(request, *args, **kwargs)
  File "C:\Python27\lib\site-packages\rest_framework\views.py", line 466, in dispatch
    response = self.handle_exception(exc)
  File "C:\Python27\lib\site-packages\rest_framework\views.py", line 463, in dispatch
    response = handler(request, *args, **kwargs)
  File "D:\work\redjango\Management\Cmdb\rests.py", line 24, in get
    ret = Methods.get('GET').get(fun)(request)
  File "D:\work\redjango\Management\Cmdb\methods\cmdb_fun.py", line 77, in group_get
    ret['data']=globals()[request.GET.get('name')](group_id)
KeyError: None
[ERROR 2016-11-24 15:06:13,578 @ 1264] (C:\Python27\lib\site-packages\django\core\handlers\base.py/handle_uncaught_exception:256) - Internal Server Error: /v1/cmdb/list/groupget/
Traceback (most recent call last):
  File "C:\Python27\lib\site-packages\django\core\handlers\base.py", line 132, in get_response
    response = wrapped_callback(request, *callback_args, **callback_kwargs)
  File "C:\Python27\lib\site-packages\django\views\decorators\csrf.py", line 58, in wrapped_view
    return view_func(*args, **kwargs)
  File "C:\Python27\lib\site-packages\django\views\generic\base.py", line 71, in view
    return self.dispatch(request, *args, **kwargs)
  File "C:\Python27\lib\site-packages\rest_framework\views.py", line 466, in dispatch
    response = self.handle_exception(exc)
  File "C:\Python27\lib\site-packages\rest_framework\views.py", line 463, in dispatch
    response = handler(request, *args, **kwargs)
  File "D:\work\redjango\Management\Cmdb\rests.py", line 24, in get
    ret = Methods.get('GET').get(fun)(request)
  File "D:\work\redjango\Management\Cmdb\methods\cmdb_fun.py", line 77, in group_get
    ret['data']=globals()[request.GET.get('name')](group_id)
KeyError: None
[ERROR 2016-11-24 15:43:43,147 @ 1264] (C:\Python27\lib\site-packages\django\core\handlers\base.py/handle_uncaught_exception:256) - Internal Server Error: /v1/cmdb/list/groupget/
Traceback (most recent call last):
  File "C:\Python27\lib\site-packages\django\core\handlers\base.py", line 132, in get_response
    response = wrapped_callback(request, *callback_args, **callback_kwargs)
  File "C:\Python27\lib\site-packages\django\views\decorators\csrf.py", line 58, in wrapped_view
    return view_func(*args, **kwargs)
  File "C:\Python27\lib\site-packages\django\views\generic\base.py", line 71, in view
    return self.dispatch(request, *args, **kwargs)
  File "C:\Python27\lib\site-packages\rest_framework\views.py", line 466, in dispatch
    response = self.handle_exception(exc)
  File "C:\Python27\lib\site-packages\rest_framework\views.py", line 463, in dispatch
    response = handler(request, *args, **kwargs)
  File "D:\work\redjango\Management\Cmdb\rests.py", line 24, in get
    ret = Methods.get('GET').get(fun)(request)
  File "D:\work\redjango\Management\Cmdb\methods\cmdb_fun.py", line 77, in group_get
    ret['data']=globals()[request.GET.get('name')](group_id)
KeyError: None
[ERROR 2016-11-24 17:32:42,897 @ 19564] (C:\Python27\lib\site-packages\django\core\handlers\base.py/handle_uncaught_exception:256) - Internal Server Error: /v1/service/list/register/
Traceback (most recent call last):
  File "C:\Python27\lib\site-packages\django\core\handlers\base.py", line 132, in get_response
    response = wrapped_callback(request, *callback_args, **callback_kwargs)
  File "C:\Python27\lib\site-packages\django\views\decorators\csrf.py", line 58, in wrapped_view
    return view_func(*args, **kwargs)
  File "C:\Python27\lib\site-packages\django\views\generic\base.py", line 71, in view
    return self.dispatch(request, *args, **kwargs)
  File "C:\Python27\lib\site-packages\rest_framework\views.py", line 466, in dispatch
    response = self.handle_exception(exc)
  File "C:\Python27\lib\site-packages\rest_framework\views.py", line 463, in dispatch
    response = handler(request, *args, **kwargs)
  File "D:\work\redjango\Management\Cmdb\rests.py", line 26, in post
    ret = Methods.get('POST').get(fun)(request)
TypeError: 'NoneType' object is not callable
[ERROR 2016-11-24 17:32:48,286 @ 19564] (C:\Python27\lib\site-packages\django\core\handlers\base.py/handle_uncaught_exception:256) - Internal Server Error: /v1/service/list/register/
Traceback (most recent call last):
  File "C:\Python27\lib\site-packages\django\core\handlers\base.py", line 132, in get_response
    response = wrapped_callback(request, *callback_args, **callback_kwargs)
  File "C:\Python27\lib\site-packages\django\views\decorators\csrf.py", line 58, in wrapped_view
    return view_func(*args, **kwargs)
  File "C:\Python27\lib\site-packages\django\views\generic\base.py", line 71, in view
    return self.dispatch(request, *args, **kwargs)
  File "C:\Python27\lib\site-packages\rest_framework\views.py", line 466, in dispatch
    response = self.handle_exception(exc)
  File "C:\Python27\lib\site-packages\rest_framework\views.py", line 463, in dispatch
    response = handler(request, *args, **kwargs)
  File "D:\work\redjango\Management\Cmdb\rests.py", line 22, in get
    ret = Methods.get('GET').get(fun)(request)
TypeError: 'NoneType' object is not callable
[ERROR 2016-11-24 17:35:16,772 @ 20032] (C:\Python27\lib\site-packages\django\core\handlers\base.py/handle_uncaught_exception:256) - Internal Server Error: /v1/service/list/register/
Traceback (most recent call last):
  File "C:\Python27\lib\site-packages\django\core\handlers\base.py", line 132, in get_response
    response = wrapped_callback(request, *callback_args, **callback_kwargs)
  File "C:\Python27\lib\site-packages\django\views\decorators\csrf.py", line 58, in wrapped_view
    return view_func(*args, **kwargs)
  File "C:\Python27\lib\site-packages\django\views\generic\base.py", line 71, in view
    return self.dispatch(request, *args, **kwargs)
  File "C:\Python27\lib\site-packages\rest_framework\views.py", line 466, in dispatch
    response = self.handle_exception(exc)
  File "C:\Python27\lib\site-packages\rest_framework\views.py", line 463, in dispatch
    response = handler(request, *args, **kwargs)
  File "D:\work\redjango\Management\service\rests.py", line 28, in post
    ret = Methods.get('POST').get(fun)(request)
TypeError: 'NoneType' object is not callable
[ERROR 2016-11-24 18:41:10,398 @ 20532] (C:\Python27\lib\site-packages\django\core\handlers\base.py/handle_uncaught_exception:256) - Internal Server Error: /v1/service/list/register/
Traceback (most recent call last):
  File "C:\Python27\lib\site-packages\django\core\handlers\base.py", line 132, in get_response
    response = wrapped_callback(request, *callback_args, **callback_kwargs)
  File "C:\Python27\lib\site-packages\django\views\decorators\csrf.py", line 58, in wrapped_view
    return view_func(*args, **kwargs)
  File "C:\Python27\lib\site-packages\django\views\generic\base.py", line 71, in view
    return self.dispatch(request, *args, **kwargs)
  File "C:\Python27\lib\site-packages\rest_framework\views.py", line 466, in dispatch
    response = self.handle_exception(exc)
  File "C:\Python27\lib\site-packages\rest_framework\views.py", line 463, in dispatch
    response = handler(request, *args, **kwargs)
  File "D:\work\redjango\Management\service\rests.py", line 23, in get
    ret = Methods.get('GET').get(fun)(request)
TypeError: 'NoneType' object is not callable
[ERROR 2016-11-25 13:51:35,299 @ 21772] (C:\Python27\lib\site-packages\django\core\handlers\base.py/handle_uncaught_exception:256) - Internal Server Error: /v1/cmdb/list/groupget/
Traceback (most recent call last):
  File "C:\Python27\lib\site-packages\django\core\handlers\base.py", line 132, in get_response
    response = wrapped_callback(request, *callback_args, **callback_kwargs)
  File "C:\Python27\lib\site-packages\django\views\decorators\csrf.py", line 58, in wrapped_view
    return view_func(*args, **kwargs)
  File "C:\Python27\lib\site-packages\django\views\generic\base.py", line 71, in view
    return self.dispatch(request, *args, **kwargs)
  File "C:\Python27\lib\site-packages\rest_framework\views.py", line 466, in dispatch
    response = self.handle_exception(exc)
  File "C:\Python27\lib\site-packages\rest_framework\views.py", line 463, in dispatch
    response = handler(request, *args, **kwargs)
  File "D:\work\redjango\Management\Cmdb\rests.py", line 22, in get
    ret = Methods.get('GET').get(fun)(request)
  File "D:\work\redjango\Management\Cmdb\methods\cmdb_fun.py", line 75, in group_get
    ret['data']=globals()[request.GET.get('name')](group_id)
KeyError: None
[ERROR 2016-11-25 13:51:58,690 @ 21772] (C:\Python27\lib\site-packages\django\core\handlers\base.py/handle_uncaught_exception:256) - Internal Server Error: /v1/cmdb/list/typelist/
Traceback (most recent call last):
  File "C:\Python27\lib\site-packages\django\core\handlers\base.py", line 132, in get_response
    response = wrapped_callback(request, *callback_args, **callback_kwargs)
  File "C:\Python27\lib\site-packages\django\views\decorators\csrf.py", line 58, in wrapped_view
    return view_func(*args, **kwargs)
  File "C:\Python27\lib\site-packages\django\views\generic\base.py", line 71, in view
    return self.dispatch(request, *args, **kwargs)
  File "C:\Python27\lib\site-packages\rest_framework\views.py", line 466, in dispatch
    response = self.handle_exception(exc)
  File "C:\Python27\lib\site-packages\rest_framework\views.py", line 463, in dispatch
    response = handler(request, *args, **kwargs)
  File "D:\work\redjango\Management\Cmdb\rests.py", line 22, in get
    ret = Methods.get('GET').get(fun)(request)
TypeError: 'NoneType' object is not callable
[ERROR 2016-11-25 13:52:08,926 @ 21772] (C:\Python27\lib\site-packages\django\core\handlers\base.py/handle_uncaught_exception:256) - Internal Server Error: /v1/service/list/register/
Traceback (most recent call last):
  File "C:\Python27\lib\site-packages\django\core\handlers\base.py", line 132, in get_response
    response = wrapped_callback(request, *callback_args, **callback_kwargs)
  File "C:\Python27\lib\site-packages\django\views\decorators\csrf.py", line 58, in wrapped_view
    return view_func(*args, **kwargs)
  File "C:\Python27\lib\site-packages\django\views\generic\base.py", line 71, in view
    return self.dispatch(request, *args, **kwargs)
  File "C:\Python27\lib\site-packages\rest_framework\views.py", line 466, in dispatch
    response = self.handle_exception(exc)
  File "C:\Python27\lib\site-packages\rest_framework\views.py", line 463, in dispatch
    response = handler(request, *args, **kwargs)
  File "D:\work\redjango\Management\service\rests.py", line 23, in get
    ret = Methods.get('GET').get(fun)(request)
TypeError: 'NoneType' object is not callable
[ERROR 2016-11-25 13:52:19,358 @ 21772] (C:\Python27\lib\site-packages\django\core\handlers\base.py/handle_uncaught_exception:256) - Internal Server Error: /v1/cmdb/list/typelist/
Traceback (most recent call last):
  File "C:\Python27\lib\site-packages\django\core\handlers\base.py", line 132, in get_response
    response = wrapped_callback(request, *callback_args, **callback_kwargs)
  File "C:\Python27\lib\site-packages\django\views\decorators\csrf.py", line 58, in wrapped_view
    return view_func(*args, **kwargs)
  File "C:\Python27\lib\site-packages\django\views\generic\base.py", line 71, in view
    return self.dispatch(request, *args, **kwargs)
  File "C:\Python27\lib\site-packages\rest_framework\views.py", line 466, in dispatch
    response = self.handle_exception(exc)
  File "C:\Python27\lib\site-packages\rest_framework\views.py", line 463, in dispatch
    response = handler(request, *args, **kwargs)
  File "D:\work\redjango\Management\Cmdb\rests.py", line 22, in get
    ret = Methods.get('GET').get(fun)(request)
TypeError: 'NoneType' object is not callable
[ERROR 2016-11-25 13:52:33,974 @ 21772] (C:\Python27\lib\site-packages\django\core\handlers\base.py/handle_uncaught_exception:256) - Internal Server Error: /v1/cmdb/list/type_list、/
Traceback (most recent call last):
  File "C:\Python27\lib\site-packages\django\core\handlers\base.py", line 132, in get_response
    response = wrapped_callback(request, *callback_args, **callback_kwargs)
  File "C:\Python27\lib\site-packages\django\views\decorators\csrf.py", line 58, in wrapped_view
    return view_func(*args, **kwargs)
  File "C:\Python27\lib\site-packages\django\views\generic\base.py", line 71, in view
    return self.dispatch(request, *args, **kwargs)
  File "C:\Python27\lib\site-packages\rest_framework\views.py", line 466, in dispatch
    response = self.handle_exception(exc)
  File "C:\Python27\lib\site-packages\rest_framework\views.py", line 463, in dispatch
    response = handler(request, *args, **kwargs)
  File "D:\work\redjango\Management\Cmdb\rests.py", line 22, in get
    ret = Methods.get('GET').get(fun)(request)
TypeError: 'NoneType' object is not callable
[ERROR 2016-11-25 13:52:39,065 @ 21772] (C:\Python27\lib\site-packages\django\core\handlers\base.py/handle_uncaught_exception:256) - Internal Server Error: /v1/cmdb/list/type_list/
Traceback (most recent call last):
  File "C:\Python27\lib\site-packages\django\core\handlers\base.py", line 132, in get_response
    response = wrapped_callback(request, *callback_args, **callback_kwargs)
  File "C:\Python27\lib\site-packages\django\views\decorators\csrf.py", line 58, in wrapped_view
    return view_func(*args, **kwargs)
  File "C:\Python27\lib\site-packages\django\views\generic\base.py", line 71, in view
    return self.dispatch(request, *args, **kwargs)
  File "C:\Python27\lib\site-packages\rest_framework\views.py", line 466, in dispatch
    response = self.handle_exception(exc)
  File "C:\Python27\lib\site-packages\rest_framework\views.py", line 463, in dispatch
    response = handler(request, *args, **kwargs)
  File "D:\work\redjango\Management\Cmdb\rests.py", line 22, in get
    ret = Methods.get('GET').get(fun)(request)
TypeError: 'NoneType' object is not callable
[ERROR 2016-11-25 13:53:31,854 @ 13880] (C:\Python27\lib\site-packages\django\core\handlers\base.py/handle_uncaught_exception:256) - Internal Server Error: /v1/cmdb/list/type_list/
Traceback (most recent call last):
  File "C:\Python27\lib\site-packages\django\core\handlers\base.py", line 132, in get_response
    response = wrapped_callback(request, *callback_args, **callback_kwargs)
  File "C:\Python27\lib\site-packages\django\views\decorators\csrf.py", line 58, in wrapped_view
    return view_func(*args, **kwargs)
  File "C:\Python27\lib\site-packages\django\views\generic\base.py", line 71, in view
    return self.dispatch(request, *args, **kwargs)
  File "C:\Python27\lib\site-packages\rest_framework\views.py", line 466, in dispatch
    response = self.handle_exception(exc)
  File "C:\Python27\lib\site-packages\rest_framework\views.py", line 463, in dispatch
    response = handler(request, *args, **kwargs)
  File "D:\work\redjango\Management\Cmdb\rests.py", line 22, in get
    ret = Methods.get('GET').get(fun)(request)
TypeError: 'NoneType' object is not callable
[ERROR 2016-11-25 15:19:20,874 @ 29836] (C:\Python27\lib\site-packages\django\core\handlers\base.py/handle_uncaught_exception:256) - Internal Server Error: /v1/service/list/query/
Traceback (most recent call last):
  File "C:\Python27\lib\site-packages\django\core\handlers\base.py", line 132, in get_response
    response = wrapped_callback(request, *callback_args, **callback_kwargs)
  File "C:\Python27\lib\site-packages\django\views\decorators\csrf.py", line 58, in wrapped_view
    return view_func(*args, **kwargs)
  File "C:\Python27\lib\site-packages\django\views\generic\base.py", line 71, in view
    return self.dispatch(request, *args, **kwargs)
  File "C:\Python27\lib\site-packages\rest_framework\views.py", line 466, in dispatch
    response = self.handle_exception(exc)
  File "C:\Python27\lib\site-packages\rest_framework\views.py", line 463, in dispatch
    response = handler(request, *args, **kwargs)
  File "D:\work\redjango\Management\service\rests.py", line 23, in get
    ret = Methods.get('GET').get(fun)(request)
  File "D:\work\redjango\Management\service\service.py", line 52, in query_host
    sys['host']=map((lambda x:x.name),service.Asset_service.all())
  File "D:\work\redjango\Management\service\service.py", line 52, in <lambda>
    sys['host']=map((lambda x:x.name),service.Asset_service.all())
AttributeError: 'Asset' object has no attribute 'name'
[ERROR 2016-11-29 10:57:12,997 @ 10100] (C:\Python27\lib\site-packages\django\core\handlers\base.py/handle_uncaught_exception:256) - Internal Server Error: /v1/cmdb/list/groupget/
Traceback (most recent call last):
  File "C:\Python27\lib\site-packages\django\core\handlers\base.py", line 132, in get_response
    response = wrapped_callback(request, *callback_args, **callback_kwargs)
  File "C:\Python27\lib\site-packages\django\views\decorators\csrf.py", line 58, in wrapped_view
    return view_func(*args, **kwargs)
  File "C:\Python27\lib\site-packages\django\views\generic\base.py", line 71, in view
    return self.dispatch(request, *args, **kwargs)
  File "C:\Python27\lib\site-packages\rest_framework\views.py", line 466, in dispatch
    response = self.handle_exception(exc)
  File "C:\Python27\lib\site-packages\rest_framework\views.py", line 463, in dispatch
    response = handler(request, *args, **kwargs)
  File "D:\work\redjango\Management\Cmdb\rests.py", line 22, in get
    ret = Methods.get('GET').get(fun)(request)
  File "D:\work\redjango\Management\Cmdb\methods\cmdb_fun.py", line 75, in group_get
    ret['data']=globals()[request.GET.get('name')](group_id)
KeyError: None
[ERROR 2016-11-30 08:57:20,042 @ 30404] (C:\Python27\lib\site-packages\django\core\handlers\base.py/handle_uncaught_exception:256) - Internal Server Error: /v1/service/list/file_dir/
Traceback (most recent call last):
  File "C:\Python27\lib\site-packages\django\core\handlers\base.py", line 132, in get_response
    response = wrapped_callback(request, *callback_args, **callback_kwargs)
  File "C:\Python27\lib\site-packages\django\views\decorators\csrf.py", line 58, in wrapped_view
    return view_func(*args, **kwargs)
  File "C:\Python27\lib\site-packages\django\views\generic\base.py", line 71, in view
    return self.dispatch(request, *args, **kwargs)
  File "C:\Python27\lib\site-packages\rest_framework\views.py", line 466, in dispatch
    response = self.handle_exception(exc)
  File "C:\Python27\lib\site-packages\rest_framework\views.py", line 463, in dispatch
    response = handler(request, *args, **kwargs)
  File "D:\work\redjango\Management\service\rests.py", line 29, in post
    return packageResponse(ret)
  File "D:\work\redjango\Management\Cmdb\methods\common.py", line 13, in packageResponse
    json_status = json.dumps(json_status)
  File "C:\Python27\lib\json\__init__.py", line 244, in dumps
    return _default_encoder.encode(obj)
  File "C:\Python27\lib\json\encoder.py", line 207, in encode
    chunks = self.iterencode(o, _one_shot=True)
  File "C:\Python27\lib\json\encoder.py", line 270, in iterencode
    return _iterencode(o, 0)
ValueError: Circular reference detected
[ERROR 2016-11-30 08:58:09,296 @ 30404] (C:\Python27\lib\site-packages\django\core\handlers\base.py/handle_uncaught_exception:256) - Internal Server Error: /v1/service/list/file_dir/
Traceback (most recent call last):
  File "C:\Python27\lib\site-packages\django\core\handlers\base.py", line 132, in get_response
    response = wrapped_callback(request, *callback_args, **callback_kwargs)
  File "C:\Python27\lib\site-packages\django\views\decorators\csrf.py", line 58, in wrapped_view
    return view_func(*args, **kwargs)
  File "C:\Python27\lib\site-packages\django\views\generic\base.py", line 71, in view
    return self.dispatch(request, *args, **kwargs)
  File "C:\Python27\lib\site-packages\rest_framework\views.py", line 466, in dispatch
    response = self.handle_exception(exc)
  File "C:\Python27\lib\site-packages\rest_framework\views.py", line 463, in dispatch
    response = handler(request, *args, **kwargs)
  File "D:\work\redjango\Management\service\rests.py", line 29, in post
    return packageResponse(ret)
  File "D:\work\redjango\Management\Cmdb\methods\common.py", line 13, in packageResponse
    json_status = json.dumps(json_status)
  File "C:\Python27\lib\json\__init__.py", line 244, in dumps
    return _default_encoder.encode(obj)
  File "C:\Python27\lib\json\encoder.py", line 207, in encode
    chunks = self.iterencode(o, _one_shot=True)
  File "C:\Python27\lib\json\encoder.py", line 270, in iterencode
    return _iterencode(o, 0)
ValueError: Circular reference detected
[ERROR 2016-11-30 09:33:17,928 @ 34356] (C:\Python27\lib\site-packages\django\core\handlers\base.py/handle_uncaught_exception:256) - Internal Server Error: /v1/service/list/register/
Traceback (most recent call last):
  File "C:\Python27\lib\site-packages\django\core\handlers\base.py", line 132, in get_response
    response = wrapped_callback(request, *callback_args, **callback_kwargs)
  File "C:\Python27\lib\site-packages\django\views\decorators\csrf.py", line 58, in wrapped_view
    return view_func(*args, **kwargs)
  File "C:\Python27\lib\site-packages\django\views\generic\base.py", line 71, in view
    return self.dispatch(request, *args, **kwargs)
  File "C:\Python27\lib\site-packages\rest_framework\views.py", line 466, in dispatch
    response = self.handle_exception(exc)
  File "C:\Python27\lib\site-packages\rest_framework\views.py", line 463, in dispatch
    response = handler(request, *args, **kwargs)
  File "D:\work\redjango\Management\service\rests.py", line 29, in post
    return packageResponse(ret)
  File "D:\work\redjango\Management\Cmdb\methods\common.py", line 13, in packageResponse
    json_status = json.dumps(json_status)
  File "C:\Python27\lib\json\__init__.py", line 244, in dumps
    return _default_encoder.encode(obj)
  File "C:\Python27\lib\json\encoder.py", line 207, in encode
    chunks = self.iterencode(o, _one_shot=True)
  File "C:\Python27\lib\json\encoder.py", line 270, in iterencode
    return _iterencode(o, 0)
  File "C:\Python27\lib\json\encoder.py", line 184, in default
    raise TypeError(repr(o) + " is not JSON serializable")
TypeError: IntegrityError(1062, "Duplicate entry '\xe7\x94\x9f\xe4\xba\xa7\xe7\x8e\xaf\xe5\xa2\x83' for key 'name_type'") is not JSON serializable
[ERROR 2016-11-30 09:34:10,411 @ 34356] (C:\Python27\lib\site-packages\django\core\handlers\base.py/handle_uncaught_exception:256) - Internal Server Error: /v1/service/list/register/
Traceback (most recent call last):
  File "C:\Python27\lib\site-packages\django\core\handlers\base.py", line 132, in get_response
    response = wrapped_callback(request, *callback_args, **callback_kwargs)
  File "C:\Python27\lib\site-packages\django\views\decorators\csrf.py", line 58, in wrapped_view
    return view_func(*args, **kwargs)
  File "C:\Python27\lib\site-packages\django\views\generic\base.py", line 71, in view
    return self.dispatch(request, *args, **kwargs)
  File "C:\Python27\lib\site-packages\rest_framework\views.py", line 466, in dispatch
    response = self.handle_exception(exc)
  File "C:\Python27\lib\site-packages\rest_framework\views.py", line 463, in dispatch
    response = handler(request, *args, **kwargs)
  File "D:\work\redjango\Management\service\rests.py", line 29, in post
    return packageResponse(ret)
  File "D:\work\redjango\Management\Cmdb\methods\common.py", line 13, in packageResponse
    json_status = json.dumps(json_status)
  File "C:\Python27\lib\json\__init__.py", line 244, in dumps
    return _default_encoder.encode(obj)
  File "C:\Python27\lib\json\encoder.py", line 207, in encode
    chunks = self.iterencode(o, _one_shot=True)
  File "C:\Python27\lib\json\encoder.py", line 270, in iterencode
    return _iterencode(o, 0)
  File "C:\Python27\lib\json\encoder.py", line 184, in default
    raise TypeError(repr(o) + " is not JSON serializable")
TypeError: IntegrityError(1062, "Duplicate entry '\xe7\x94\x9f\xe4\xba\xa7\xe7\x8e\xaf\xe5\xa2\x83' for key 'name_type'") is not JSON serializable
[ERROR 2016-11-30 09:49:00,053 @ 34288] (C:\Python27\lib\site-packages\django\core\handlers\base.py/handle_uncaught_exception:256) - Internal Server Error: /v1/service/list/type_list/
Traceback (most recent call last):
  File "C:\Python27\lib\site-packages\django\core\handlers\base.py", line 132, in get_response
    response = wrapped_callback(request, *callback_args, **callback_kwargs)
  File "C:\Python27\lib\site-packages\django\views\decorators\csrf.py", line 58, in wrapped_view
    return view_func(*args, **kwargs)
  File "C:\Python27\lib\site-packages\django\views\generic\base.py", line 71, in view
    return self.dispatch(request, *args, **kwargs)
  File "C:\Python27\lib\site-packages\rest_framework\views.py", line 466, in dispatch
    response = self.handle_exception(exc)
  File "C:\Python27\lib\site-packages\rest_framework\views.py", line 463, in dispatch
    response = handler(request, *args, **kwargs)
  File "D:\work\redjango\Management\service\rests.py", line 23, in get
    ret = Methods.get('GET').get(fun)(request)
  File "D:\work\redjango\Management\service\service.py", line 35, in type_list
    list_data=list(set([i.name_type for i in Register.objects.all()]))
  File "C:\Python27\lib\site-packages\django\db\models\query.py", line 162, in __iter__
    self._fetch_all()
  File "C:\Python27\lib\site-packages\django\db\models\query.py", line 965, in _fetch_all
    self._result_cache = list(self.iterator())
  File "C:\Python27\lib\site-packages\django\db\models\query.py", line 238, in iterator
    results = compiler.execute_sql()
  File "C:\Python27\lib\site-packages\django\db\models\sql\compiler.py", line 840, in execute_sql
    cursor.execute(sql, params)
  File "C:\Python27\lib\site-packages\django\db\backends\utils.py", line 79, in execute
    return super(CursorDebugWrapper, self).execute(sql, params)
  File "C:\Python27\lib\site-packages\django\db\backends\utils.py", line 64, in execute
    return self.cursor.execute(sql, params)
  File "C:\Python27\lib\site-packages\django\db\utils.py", line 98, in __exit__
    six.reraise(dj_exc_type, dj_exc_value, traceback)
  File "C:\Python27\lib\site-packages\django\db\backends\utils.py", line 64, in execute
    return self.cursor.execute(sql, params)
  File "C:\Python27\lib\site-packages\django\db\backends\mysql\base.py", line 124, in execute
    return self.cursor.execute(query, args)
  File "C:\Python27\lib\site-packages\MySQLdb\cursors.py", line 174, in execute
    self.errorhandler(self, exc, value)
  File "C:\Python27\lib\site-packages\MySQLdb\connections.py", line 36, in defaulterrorhandler
    raise errorclass, errorvalue
ProgrammingError: (1146, "Table 'cmdb.service_register' doesn't exist")
[ERROR 2016-11-30 10:20:13,989 @ 35076] (C:\Python27\lib\site-packages\django\core\handlers\base.py/handle_uncaught_exception:256) - Internal Server Error: /v1/cmdb/list/groupget/
Traceback (most recent call last):
  File "C:\Python27\lib\site-packages\django\core\handlers\base.py", line 132, in get_response
    response = wrapped_callback(request, *callback_args, **callback_kwargs)
  File "C:\Python27\lib\site-packages\django\views\decorators\csrf.py", line 58, in wrapped_view
    return view_func(*args, **kwargs)
  File "C:\Python27\lib\site-packages\django\views\generic\base.py", line 71, in view
    return self.dispatch(request, *args, **kwargs)
  File "C:\Python27\lib\site-packages\rest_framework\views.py", line 466, in dispatch
    response = self.handle_exception(exc)
  File "C:\Python27\lib\site-packages\rest_framework\views.py", line 463, in dispatch
    response = handler(request, *args, **kwargs)
  File "D:\work\redjango\Management\Cmdb\rests.py", line 22, in get
    ret = Methods.get('GET').get(fun)(request)
  File "D:\work\redjango\Management\Cmdb\methods\cmdb_fun.py", line 75, in group_get
    ret['data']=globals()[request.GET.get('name')](group_id)
KeyError: None
[ERROR 2016-11-30 10:32:43,138 @ 35076] (C:\Python27\lib\site-packages\django\core\handlers\base.py/handle_uncaught_exception:256) - Internal Server Error: /v1/cmdb/list/groupget/
Traceback (most recent call last):
  File "C:\Python27\lib\site-packages\django\core\handlers\base.py", line 132, in get_response
    response = wrapped_callback(request, *callback_args, **callback_kwargs)
  File "C:\Python27\lib\site-packages\django\views\decorators\csrf.py", line 58, in wrapped_view
    return view_func(*args, **kwargs)
  File "C:\Python27\lib\site-packages\django\views\generic\base.py", line 71, in view
    return self.dispatch(request, *args, **kwargs)
  File "C:\Python27\lib\site-packages\rest_framework\views.py", line 466, in dispatch
    response = self.handle_exception(exc)
  File "C:\Python27\lib\site-packages\rest_framework\views.py", line 463, in dispatch
    response = handler(request, *args, **kwargs)
  File "D:\work\redjango\Management\Cmdb\rests.py", line 22, in get
    ret = Methods.get('GET').get(fun)(request)
  File "D:\work\redjango\Management\Cmdb\methods\cmdb_fun.py", line 75, in group_get
    ret['data']=globals()[request.GET.get('name')](group_id)
KeyError: None
[ERROR 2016-11-30 15:39:31,920 @ 18476] (C:\Python27\lib\site-packages\django\core\handlers\base.py/handle_uncaught_exception:256) - Internal Server Error: /v1/service/list/register/
Traceback (most recent call last):
  File "C:\Python27\lib\site-packages\django\core\handlers\base.py", line 132, in get_response
    response = wrapped_callback(request, *callback_args, **callback_kwargs)
  File "C:\Python27\lib\site-packages\django\views\decorators\csrf.py", line 58, in wrapped_view
    return view_func(*args, **kwargs)
  File "C:\Python27\lib\site-packages\django\views\generic\base.py", line 71, in view
    return self.dispatch(request, *args, **kwargs)
  File "C:\Python27\lib\site-packages\rest_framework\views.py", line 466, in dispatch
    response = self.handle_exception(exc)
  File "C:\Python27\lib\site-packages\rest_framework\views.py", line 463, in dispatch
    response = handler(request, *args, **kwargs)
  File "D:\work\redjango\Management\service\rests.py", line 29, in post
    return packageResponse(ret)
  File "D:\work\redjango\Management\Cmdb\methods\common.py", line 13, in packageResponse
    json_status = json.dumps(json_status)
  File "C:\Python27\lib\json\__init__.py", line 244, in dumps
    return _default_encoder.encode(obj)
  File "C:\Python27\lib\json\encoder.py", line 207, in encode
    chunks = self.iterencode(o, _one_shot=True)
  File "C:\Python27\lib\json\encoder.py", line 270, in iterencode
    return _iterencode(o, 0)
  File "C:\Python27\lib\json\encoder.py", line 184, in default
    raise TypeError(repr(o) + " is not JSON serializable")
TypeError: IntegrityError(1062, "Duplicate entry 'crm' for key 'service_name'") is not JSON serializable
[ERROR 2016-11-30 15:41:53,220 @ 18576] (C:\Python27\lib\site-packages\django\core\handlers\base.py/handle_uncaught_exception:256) - Internal Server Error: /v1/service/list/file_dir/
Traceback (most recent call last):
  File "C:\Python27\lib\site-packages\django\core\handlers\base.py", line 132, in get_response
    response = wrapped_callback(request, *callback_args, **callback_kwargs)
  File "C:\Python27\lib\site-packages\django\views\decorators\csrf.py", line 58, in wrapped_view
    return view_func(*args, **kwargs)
  File "C:\Python27\lib\site-packages\django\views\generic\base.py", line 71, in view
    return self.dispatch(request, *args, **kwargs)
  File "C:\Python27\lib\site-packages\rest_framework\views.py", line 466, in dispatch
    response = self.handle_exception(exc)
  File "C:\Python27\lib\site-packages\rest_framework\views.py", line 463, in dispatch
    response = handler(request, *args, **kwargs)
  File "D:\work\redjango\Management\service\rests.py", line 28, in post
    ret = Methods.get('POST').get(fun)(request)
  File "D:\work\redjango\Management\service\service.py", line 69, in file_dir
    print Asset.objects.get(hostname=per_host).register_set.all()
  File "C:\Python27\lib\site-packages\django\db\models\manager.py", line 127, in manager_method
    return getattr(self.get_queryset(), name)(*args, **kwargs)
  File "C:\Python27\lib\site-packages\django\db\models\query.py", line 334, in get
    self.model._meta.object_name
DoesNotExist: Asset matching query does not exist.
[ERROR 2016-11-30 15:42:01,246 @ 18576] (C:\Python27\lib\site-packages\django\core\handlers\base.py/handle_uncaught_exception:256) - Internal Server Error: /v1/service/list/file_dir/
Traceback (most recent call last):
  File "C:\Python27\lib\site-packages\django\core\handlers\base.py", line 132, in get_response
    response = wrapped_callback(request, *callback_args, **callback_kwargs)
  File "C:\Python27\lib\site-packages\django\views\decorators\csrf.py", line 58, in wrapped_view
    return view_func(*args, **kwargs)
  File "C:\Python27\lib\site-packages\django\views\generic\base.py", line 71, in view
    return self.dispatch(request, *args, **kwargs)
  File "C:\Python27\lib\site-packages\rest_framework\views.py", line 466, in dispatch
    response = self.handle_exception(exc)
  File "C:\Python27\lib\site-packages\rest_framework\views.py", line 463, in dispatch
    response = handler(request, *args, **kwargs)
  File "D:\work\redjango\Management\service\rests.py", line 28, in post
    ret = Methods.get('POST').get(fun)(request)
  File "D:\work\redjango\Management\service\service.py", line 69, in file_dir
    print Asset.objects.get(hostname=per_host).register_set.all()
  File "C:\Python27\lib\site-packages\django\db\models\manager.py", line 127, in manager_method
    return getattr(self.get_queryset(), name)(*args, **kwargs)
  File "C:\Python27\lib\site-packages\django\db\models\query.py", line 334, in get
    self.model._meta.object_name
DoesNotExist: Asset matching query does not exist.
[ERROR 2016-11-30 15:42:05,250 @ 18576] (C:\Python27\lib\site-packages\django\core\handlers\base.py/handle_uncaught_exception:256) - Internal Server Error: /v1/service/list/file_dir/
Traceback (most recent call last):
  File "C:\Python27\lib\site-packages\django\core\handlers\base.py", line 132, in get_response
    response = wrapped_callback(request, *callback_args, **callback_kwargs)
  File "C:\Python27\lib\site-packages\django\views\decorators\csrf.py", line 58, in wrapped_view
    return view_func(*args, **kwargs)
  File "C:\Python27\lib\site-packages\django\views\generic\base.py", line 71, in view
    return self.dispatch(request, *args, **kwargs)
  File "C:\Python27\lib\site-packages\rest_framework\views.py", line 466, in dispatch
    response = self.handle_exception(exc)
  File "C:\Python27\lib\site-packages\rest_framework\views.py", line 463, in dispatch
    response = handler(request, *args, **kwargs)
  File "D:\work\redjango\Management\service\rests.py", line 28, in post
    ret = Methods.get('POST').get(fun)(request)
  File "D:\work\redjango\Management\service\service.py", line 69, in file_dir
    print Asset.objects.get(hostname=per_host).register_set.all()
  File "C:\Python27\lib\site-packages\django\db\models\manager.py", line 127, in manager_method
    return getattr(self.get_queryset(), name)(*args, **kwargs)
  File "C:\Python27\lib\site-packages\django\db\models\query.py", line 334, in get
    self.model._meta.object_name
DoesNotExist: Asset matching query does not exist.
[ERROR 2016-11-30 16:47:19,855 @ 37100] (C:\Python27\lib\site-packages\django\core\handlers\base.py/handle_uncaught_exception:256) - Internal Server Error: /v1/service/list/file_dir/
Traceback (most recent call last):
  File "C:\Python27\lib\site-packages\django\core\handlers\base.py", line 132, in get_response
    response = wrapped_callback(request, *callback_args, **callback_kwargs)
  File "C:\Python27\lib\site-packages\django\views\decorators\csrf.py", line 58, in wrapped_view
    return view_func(*args, **kwargs)
  File "C:\Python27\lib\site-packages\django\views\generic\base.py", line 71, in view
    return self.dispatch(request, *args, **kwargs)
  File "C:\Python27\lib\site-packages\rest_framework\views.py", line 466, in dispatch
    response = self.handle_exception(exc)
  File "C:\Python27\lib\site-packages\rest_framework\views.py", line 463, in dispatch
    response = handler(request, *args, **kwargs)
  File "D:\work\redjango\Management\service\rests.py", line 28, in post
    ret = Methods.get('POST').get(fun)(request)
  File "D:\work\redjango\Management\service\service.py", line 80, in file_dir
    print path_replace(per_host_d['path_project'],host_d['path_project'],json.loads(request.POST.get('path_list')))
  File "D:\work\redjango\Management\Cmdb\methods\common.py", line 65, in path_replace
    ret[i]='e'
TypeError: unhashable type: 'dict'
[ERROR 2016-11-30 16:48:50,957 @ 36436] (C:\Python27\lib\site-packages\django\core\handlers\base.py/handle_uncaught_exception:256) - Internal Server Error: /v1/service/list/file_dir/
Traceback (most recent call last):
  File "C:\Python27\lib\site-packages\django\core\handlers\base.py", line 132, in get_response
    response = wrapped_callback(request, *callback_args, **callback_kwargs)
  File "C:\Python27\lib\site-packages\django\views\decorators\csrf.py", line 58, in wrapped_view
    return view_func(*args, **kwargs)
  File "C:\Python27\lib\site-packages\django\views\generic\base.py", line 71, in view
    return self.dispatch(request, *args, **kwargs)
  File "C:\Python27\lib\site-packages\rest_framework\views.py", line 466, in dispatch
    response = self.handle_exception(exc)
  File "C:\Python27\lib\site-packages\rest_framework\views.py", line 463, in dispatch
    response = handler(request, *args, **kwargs)
  File "D:\work\redjango\Management\service\rests.py", line 28, in post
    ret = Methods.get('POST').get(fun)(request)
  File "D:\work\redjango\Management\service\service.py", line 80, in file_dir
    print path_replace(per_host_d['path_project'],host_d['path_project'],json.loads(request.POST.get('path_list')))
  File "D:\work\redjango\Management\Cmdb\methods\common.py", line 65, in path_replace
    ret[i]='e'
TypeError: unhashable type: 'dict'
[ERROR 2016-11-30 16:49:39,984 @ 17648] (C:\Python27\lib\site-packages\django\core\handlers\base.py/handle_uncaught_exception:256) - Internal Server Error: /v1/service/list/file_dir/
Traceback (most recent call last):
  File "C:\Python27\lib\site-packages\django\core\handlers\base.py", line 132, in get_response
    response = wrapped_callback(request, *callback_args, **callback_kwargs)
  File "C:\Python27\lib\site-packages\django\views\decorators\csrf.py", line 58, in wrapped_view
    return view_func(*args, **kwargs)
  File "C:\Python27\lib\site-packages\django\views\generic\base.py", line 71, in view
    return self.dispatch(request, *args, **kwargs)
  File "C:\Python27\lib\site-packages\rest_framework\views.py", line 466, in dispatch
    response = self.handle_exception(exc)
  File "C:\Python27\lib\site-packages\rest_framework\views.py", line 463, in dispatch
    response = handler(request, *args, **kwargs)
  File "D:\work\redjango\Management\service\rests.py", line 28, in post
    ret = Methods.get('POST').get(fun)(request)
  File "D:\work\redjango\Management\service\service.py", line 80, in file_dir
    print path_replace(per_host_d['path_project'],host_d['path_project'],json.loads(request.POST.get('path_list')))
  File "D:\work\redjango\Management\Cmdb\methods\common.py", line 66, in path_replace
    ret[i]='e'
TypeError: unhashable type: 'dict'
[ERROR 2016-11-30 16:50:32,917 @ 35208] (C:\Python27\lib\site-packages\django\core\handlers\base.py/handle_uncaught_exception:256) - Internal Server Error: /v1/service/list/file_dir/
Traceback (most recent call last):
  File "C:\Python27\lib\site-packages\django\core\handlers\base.py", line 132, in get_response
    response = wrapped_callback(request, *callback_args, **callback_kwargs)
  File "C:\Python27\lib\site-packages\django\views\decorators\csrf.py", line 58, in wrapped_view
    return view_func(*args, **kwargs)
  File "C:\Python27\lib\site-packages\django\views\generic\base.py", line 71, in view
    return self.dispatch(request, *args, **kwargs)
  File "C:\Python27\lib\site-packages\rest_framework\views.py", line 466, in dispatch
    response = self.handle_exception(exc)
  File "C:\Python27\lib\site-packages\rest_framework\views.py", line 463, in dispatch
    response = handler(request, *args, **kwargs)
  File "D:\work\redjango\Management\service\rests.py", line 28, in post
    ret = Methods.get('POST').get(fun)(request)
  File "D:\work\redjango\Management\service\service.py", line 80, in file_dir
    print path_replace(per_host_d['path_project'],host_d['path_project'],json.loads(request.POST.get('path_list')))
  File "D:\work\redjango\Management\Cmdb\methods\common.py", line 67, in path_replace
    ret[i]='e'
TypeError: unhashable type: 'dict'
[ERROR 2016-11-30 16:54:53,424 @ 11908] (C:\Python27\lib\site-packages\django\core\handlers\base.py/handle_uncaught_exception:256) - Internal Server Error: /v1/service/list/file_dir/
Traceback (most recent call last):
  File "C:\Python27\lib\site-packages\django\core\handlers\base.py", line 132, in get_response
    response = wrapped_callback(request, *callback_args, **callback_kwargs)
  File "C:\Python27\lib\site-packages\django\views\decorators\csrf.py", line 58, in wrapped_view
    return view_func(*args, **kwargs)
  File "C:\Python27\lib\site-packages\django\views\generic\base.py", line 71, in view
    return self.dispatch(request, *args, **kwargs)
  File "C:\Python27\lib\site-packages\rest_framework\views.py", line 466, in dispatch
    response = self.handle_exception(exc)
  File "C:\Python27\lib\site-packages\rest_framework\views.py", line 463, in dispatch
    response = handler(request, *args, **kwargs)
  File "D:\work\redjango\Management\service\rests.py", line 28, in post
    ret = Methods.get('POST').get(fun)(request)
  File "D:\work\redjango\Management\service\service.py", line 80, in file_dir
    print path_replace(per_host_d['path_project'],host_d['path_project'],json.loads(request.POST.get('path_list')))
  File "D:\work\redjango\Management\Cmdb\methods\common.py", line 67, in path_replace
    file_list['type']='e'
TypeError: list indices must be integers, not str
[ERROR 2016-11-30 17:25:27,933 @ 35908] (C:\Python27\lib\site-packages\django\core\handlers\base.py/handle_uncaught_exception:256) - Internal Server Error: /v1/service/list/file_dir/
Traceback (most recent call last):
  File "C:\Python27\lib\site-packages\django\core\handlers\base.py", line 132, in get_response
    response = wrapped_callback(request, *callback_args, **callback_kwargs)
  File "C:\Python27\lib\site-packages\django\views\decorators\csrf.py", line 58, in wrapped_view
    return view_func(*args, **kwargs)
  File "C:\Python27\lib\site-packages\django\views\generic\base.py", line 71, in view
    return self.dispatch(request, *args, **kwargs)
  File "C:\Python27\lib\site-packages\rest_framework\views.py", line 466, in dispatch
    response = self.handle_exception(exc)
  File "C:\Python27\lib\site-packages\rest_framework\views.py", line 463, in dispatch
    response = handler(request, *args, **kwargs)
  File "D:\work\redjango\Management\service\rests.py", line 28, in post
    ret = Methods.get('POST').get(fun)(request)
  File "D:\work\redjango\Management\service\service.py", line 69, in file_dir
    print Asset.objects.get(hostname=per_host).register_set.all()
  File "C:\Python27\lib\site-packages\django\db\models\manager.py", line 127, in manager_method
    return getattr(self.get_queryset(), name)(*args, **kwargs)
  File "C:\Python27\lib\site-packages\django\db\models\query.py", line 334, in get
    self.model._meta.object_name
DoesNotExist: Asset matching query does not exist.
